<?xml version="1.0"?>
<robot xmlns:xacro="http://www.ros.org/wiki/xacro" name="ugv">
    <xacro:macro name="ugv">
    
      <xacro:macro name="wheel_link" params="name">
        <link name="${name}">
          <visual>
            <geometry>
              <cylinder radius="0.15" length="0.08"/>
            </geometry>
            <origin xyz="0 0 0" rpy="0 1.5708 0"/>
            <material name="Black">
              <color rgba="0.1 0.1 0.1 1"/>
            </material>
          </visual>
          <collision>
            <geometry>
              <cylinder radius="0.15" length="0.08"/>
            </geometry>
            <origin xyz="0 0 0" rpy="0 1.5708 0"/>
          </collision>
          <inertial>
            <mass value="5"/>
            <origin xyz="0 0 0"/>
            <inertia ixx="0.1" iyy="0.1" izz="0.2" ixy="0" ixz="0" iyz="0"/>
          </inertial>
        </link>
      </xacro:macro>

    
      <link name="base_footprint" />

      <link name="base_link">
        <visual>
          <geometry>
            <box size="1.8 1.0 0.8"/>
          </geometry>
          <material name="ChassisColor">
            <color rgba="0.5 0.5 0.5 1"/>
          </material>
        </visual>
        <collision>
          <geometry>
            <box size="1.8 1.0 0.8"/>
          </geometry>
        </collision>
        <inertial>
          <mass value="120"/>
          <origin xyz="0 0 0"/>
          <inertia ixx="12" iyy="12" izz="20" ixy="0" ixz="0" iyz="0"/>
        </inertial>
      </link>


      <xacro:wheel_link name="wheel_left_0"/>
      <xacro:wheel_link name="wheel_left_1"/>
      <xacro:wheel_link name="wheel_left_2"/>
      <xacro:wheel_link name="wheel_right_0"/>
      <xacro:wheel_link name="wheel_right_1"/>
      <xacro:wheel_link name="wheel_right_2"/>

    

      <link name="lidar_front">
        <visual>
          <geometry>
            <cylinder radius="0.07" length="0.08"/>
          </geometry>
          <material name="Blue">
            <color rgba="0.1 0.3 0.8 1"/>
          </material>
        </visual>
        <collision>
          <geometry>
            <cylinder radius="0.07" length="0.08"/>
          </geometry>
        </collision>
        <inertial>
          <mass value="0.1"/>
          <origin xyz="0 0 0"/>
          <inertia ixx="1e-5" iyy="1e-5" izz="1e-5" ixy="0" ixz="0" iyz="0"/>
        </inertial>
      </link>

      <link name="lidar_back">
        <visual>
          <geometry>
            <cylinder radius="0.07" length="0.08"/>
          </geometry>
          <material name="Blue">
            <color rgba="0.1 0.3 0.8 1"/>
          </material>
        </visual>
        <collision>
          <geometry>
            <cylinder radius="0.07" length="0.08"/>
          </geometry>
        </collision>
        <inertial>
          <mass value="0.1"/>
          <origin xyz="0 0 0"/>
          <inertia ixx="1e-5" iyy="1e-5" izz="1e-5" ixy="0" ixz="0" iyz="0"/>
        </inertial>
      </link>

      <link name="camera_front">
        <visual>
          <geometry>
            <box size="0.09 0.07 0.08"/>
          </geometry>
          <material name="Green">
            <color rgba="0.1 0.7 0.1 1"/>
          </material>
        </visual>
      </link>

      <link name="camera_back">
        <visual>
          <geometry>
            <box size="0.09 0.07 0.08"/>
          </geometry>
          <material name="Green">
            <color rgba="0.1 0.7 0.1 1"/>
          </material>
        </visual>
      </link>

    
      <joint name="base_joint" type="fixed">
        <parent link="base_footprint"/>
        <child link="base_link"/>
        <origin xyz="0 0 0" rpy="0 0 0"/>
      </joint>

    
      <joint name="joint_wheel_left_0" type="continuous">
        <parent link="base_link"/>
        <child link="wheel_left_0"/>
        <origin xyz="-0.8 -0.55 -0.35" rpy="0 0 1.57"/>
        <axis xyz="1 0 0"/>
      </joint>
      <joint name="joint_wheel_left_1" type="continuous">
        <parent link="base_link"/>
        <child link="wheel_left_1"/>
        <origin xyz="0 -0.55 -0.35" rpy="0 0 1.57"/>
        <axis xyz="1 0 0"/>
      </joint>
      <joint name="joint_wheel_left_2" type="continuous">
        <parent link="base_link"/>
        <child link="wheel_left_2"/>
        <origin xyz="0.8 -0.55 -0.35" rpy="0 0 1.57"/>
        <axis xyz="1 0 0"/>
      </joint>
      <joint name="joint_wheel_right_0" type="continuous">
        <parent link="base_link"/>
        <child link="wheel_right_0"/>
        <origin xyz="0.8 0.55 -0.35" rpy="0 0 1.57"/>
        <axis xyz="1 0 0"/>
      </joint>
      <joint name="joint_wheel_right_1" type="continuous">
        <parent link="base_link"/>
        <child link="wheel_right_1"/>
        <origin xyz="0 0.55 -0.35" rpy="0 0 1.57"/>
        <axis xyz="1 0 0"/>
      </joint>
      <joint name="joint_wheel_right_2" type="continuous">
        <parent link="base_link"/>
        <child link="wheel_right_2"/>
        <origin xyz="-0.8 0.55 -0.35" rpy="0 0 1.57"/>
        <axis xyz="1 0 0"/>
      </joint>

    
      <joint name="joint_lidar_front" type="fixed">
        <parent link="base_link"/>
        <child link="lidar_front"/>
        <origin xyz="0.82 0 0.44" rpy="0 0 0"/>
      </joint>

      <joint name="joint_lidar_back" type="fixed">
        <parent link="base_link"/>
        <child link="lidar_back"/>
        <origin xyz="-0.82 0 0.44" rpy="0 0 3.14159"/>
      </joint>

      <joint name="joint_camera_front" type="fixed">
        <parent link="base_link"/>
        <child link="camera_front"/>
        <origin xyz="0.75 0.14 0.44" rpy="0 0 0"/>
      </joint>

      <joint name="joint_camera_back" type="fixed">
        <parent link="base_link"/>
        <child link="camera_back"/>
        <origin xyz="-0.75 -0.14 0.44" rpy="0 0 3.14159"/>
      </joint>

    </xacro:macro>

</robot>
